Workbook

Sheet Dashboard
B2: FINANCIAL PERFORMANCE DASHBOARD
B4: Stripe · Xero · Meta Ads · Bank · Credit Card · Invoice Uploads (5,000-row capacity) · IFRS & US GAAP | Period: Apr-2026 – Jun-2026 (sample data)
B6: TOTAL REVENUE (Blended, AED) | E6: TOTAL EXPENSES (AED) | H6: NET PROFIT (AED) | K6: AR OUTSTANDING (AED)
B7: =Revenue_Summary!B34 -> 1097886.6 | E7: =Expense_Summary!E41 -> 381575.26 | H7: =Revenue_Summary!B34-Expense_Summary!E41 -> 716311.37 | K7: =Receivables!F71 -> 466237.76
B11: META AD SPEND (Gross, AED) | E11: CASH BALANCE (latest, AED) | H11: AR — UAE (AED) | K11: AR — SINGAPORE (AED)
B12: =Expense_Summary!E22 -> 65447.8 | E12: =INDEX(Bank_Raw!F4:F44,COUNT(Bank_Raw!F4:F44)) -> 499639.33 | H12: =Receivables!F68 -> 129991.27 | K12: =Receivables!F69 -> 133105.21
B16: CREDIT CARD SPEND (AED) | E16: VENDOR UPLOAD EXPENSES (AED) | H16: AP OUTSTANDING (AED) | K16: CUSTOMER INVOICE REVENUE (AED)
B17: =Expense_Summary!E30 -> 51592.82 | E17: =Expense_Summary!E38 -> 52714.23 | H17: =Payables!F76 -> 12033.26 | K17: =Revenue_Summary!E26 -> 172509.13
B21: NET PROFIT — IFRS (AED) | E21: NET INCOME — US GAAP (AED) | H21: TRIAL BALANCE STATUS | K21: STRIPE RECEIVABLES: OPEN (AED)
B22: =Financial_Statements_IFRS!C27 -> 731093.09 | E22: =Financial_Statements_GAAP!C26 -> 731093.09 | H22: =Trial_Balance!C41 -> ✓ BALANCED | K22: =Customer_Receivables_Report!G34 -> 67404.49
B26: META COST RECOVERY GAP (AED) | E26: META RECOVERY RATE | H26: CUSTOMERS ON FILE | K26: SUBSCRIPTIONS DUE THIS MONTH
B27: =Meta_Cost_Recovery!G23 -> -26062.68 | E27: =Meta_Cost_Recovery!H23 -> 1.3982209 | H27: =COUNTA(Customer_Master!A4:A5003) -> 12 | K27: =COUNTIF(Subscription_Invoicing!G5:G200,"⚠ Due") -> 2
B32: REVENUE BY CATEGORY | H32: MONTHLY REVENUE TREND (STRIPE + XERO)
B50: EXPENSE BREAKDOWN (Xero Bills) | H50: AR OUTSTANDING BY COUNTRY
B68: META AD SPEND BY CUSTOMER (Gross) | H68: ACCOUNTS PAYABLE BY VENDOR
B86: XERO RECEIVABLES BY STATUS (Total) | H86: STRIPE RECEIVABLES BY STATUS (Total)
B104: WORKBOOK GUIDE
B105: README_Setup | D105: How to connect Stripe/Xero via Power Query, or upload PDF/Word/Excel documents for Claude to extract
B106: Assumptions | D106: Edit category keywords & customer→country map here — flows through whole workbook
B107: Customer_Master | D107: Customer directory — IDs across Xero/Stripe/Meta, country, plan, relationship owner
B108: Stripe_Raw / Xero_Raw / Bank_Raw / Meta_Invoices | D108: Raw data from exports/APIs — all pre-formulated for up to 5,000 rows
B109: Credit_Card_Upload / Customer_Invoices_Upload / Vendor_Invoices_Upload | D109: Upload zones for PDF/Word/Excel source documents — 5,000-row capacity
B110: Expenses_Upload / Revenue_Upload | D110: Catch-all upload zones for misc expenses and "any other services" revenue
B111: Stripe_Invoices_Upload | D111: Stripe Invoicing receivables (Draft/Open/Paid/Void/Uncollectible)
B112: Document_Log | D112: Audit trail of every source document processed
B113: Revenue_Summary / Expense_Summary / Receivables / Payables | D113: Formula-driven analysis feeding this Dashboard
B114: Customer_Receivables_Report | D114: Per-customer invoice status breakdown — Xero AND Stripe, incl. Void/Draft/Unsent
B115: Meta_Cost_Recovery | D115: Meta ad spend cost vs. amount recovered from customers via Stripe or tagged bank transfers
B116: Subscription_Invoicing | D116: Month-by-month recurring billing schedule — shows who’s due to be invoiced and who already has been
... B119: Financial_Statements_GAAP | D119: Income Statement, Balance Sheet, Cash Flows (US GAAP terminology/ordering)

Sheet README_Setup
B2: HOW THIS DASHBOARD IS BUILT & HOW TO CONNECT LIVE DATA
B4: This workbook is fully formula-driven. It currently contains realistic SAMPLE data so you can see how every number is calculated. Replace the sample rows in the raw tabs with your real data (via Power Query refresh OR manual paste) and every summary, KPI card and chart on the Dashboard recalculates automatically.
B7: 1. WHY THIS CAN’T BE A LIVE, SELF-REFRESHING FILE OUT OF THE BOX
B8: A standalone .xlsx file cannot hold live API credentials or run a background service — Stripe and Xero both require an authenticated API call (Stripe: secret key; Xero: OAuth2 token that expires and must be refreshed). The safe, standard way to get this data into Excel is Power Query, which runs locally on your machine using YOUR credentials — Anthropic/Claude never sees or stores your keys.
B11: 2. CONNECTING STRIPE VIA POWER QUERY (refreshable, no add-in needed)
B12: • In Excel: Data tab → Get Data → From Other Sources → Blank Query → Advanced Editor. Paste the M code below, replacing YOUR_SECRET_KEY with your Stripe secret key (Developers → API keys in the Stripe Dashboard). Use a RESTRICTED key with read-only access to Charges/Payouts.
B14: let
B15: Source = Json.Document(Web.Contents("https://api.stripe.com/v1/charges",
B16: [Headers=[Authorization="Bearer YOUR_SECRET_KEY"]])),
B17: data = Source[data],
B18: #"Converted to Table" = Table.FromList(data, Splitter.SplitByNothing(), null, null, ExtraValues.Error),
B19: #"Expanded" = Table.ExpandRecordColumn(#"Converted to Table", "Column1",
... B98: Customer_Master is the single directory of customer identifiers (Xero contact ID, Stripe customer ID, Meta ad account ID) and metadata (country, industry, relationship owner, payment terms). It doesn’t feed formulas elsewhere automatically — the Assumptions country map is what drives country lookups — but it’s the reference sheet to keep both in sync when you add a new customer.

Sheet Stripe_Raw
A1: STRIPE — RAW TRANSACTION EXPORT (paste your Stripe Payments export below, starting row 4)
A2: Source: Stripe Dashboard > Payments > Export, or Power Query (see README_Setup). Replace sample data below with real export — keep same column order. This tab is pre-formulated for up to 5,000 rows (through row 5003) — just paste your data starting row 4.
A3: Date | B3: Customer | C3: Description | D3: Product/Line Item | E3: Gross Amount (AED) | F3: Stripe Fee (AED) | G3: Net Amount (AED) | H3: Currency | I3: Status | J3: Category (auto)
A4: 46113 | B4: Almoudi Group Tabuk ST | C4: WhatsApp API - Monthly Usage - Almoudi | D4: WhatsApp API - Monthly Usage | E4: 13554.67 | F4: 394.29 | G4: 13160.38 | H4: AED | I4: Paid | J4: =IFERROR(IF(ISNUMBER(SEARCH(Assumptions!$C$5,D4)),Assumptions!$D$5,IF(ISNUMBER(SEARCH(Assumptions!$C$6,D4)),Assumptions!$D$6,IF(ISNUMBER(SEARCH(Assumptions!$C$7,D4)),Assumptions!$D$7,"Other Services"))),"Other Services") -> WhatsApp
A5: 46116 | B5: Jarir Bookstore | C5: Development Retainer - Monthly - Jarir | D5: Development Retainer - Monthly | E5: 12439.23 | F5: 361.94 | G5: 12077.29 | H5: AED | I5: Paid | J5: =IF(D5="","",IFERROR(IF(ISNUMBER(SEARCH(Assumptions!$C$5,D5)),Assumptions!$D$5,IF(ISNUMBER(SEARCH(Assumptions!$C$6,D5)),Assumptions!$D$6,IF(ISNUMBER(SEARCH(Assumptions!$C$7,D5)),Assumptions!$D$7,"Other Services"))),"Other Services")) -> Development
A6: 46126 | B6: United Homeware Company (Nice) | C6: Custom Development - Sprint Invoice - United | D6: Custom Development - Sprint Invoice | E6: 1346.66 | F6: 40.25 | G6: 1306.41 | H6: AED | I6: Paid | J6: =IF(D6="","",IFERROR(IF(ISNUMBER(SEARCH(Assumptions!$C$5,D6)),Assumptions!$D$5,IF(ISNUMBER(SEARCH(Assumptions!$C$6,D6)),Assumptions!$D$6,IF(ISNUMBER(SEARCH(Assumptions!$C$7,D6)),Assumptions!$D$7,"Other Services"))),"Other Services")) -> Development
A7: 46132 | B7: Merck Serono Middle East FZ-Ltd | C7: Custom Development - Sprint Invoice - Merck | D7: Custom Development - Sprint Invoice | E7: 1256.42 | F7: 37.64 | G7: 1218.78 | H7: AED | I7: Paid | J7: =IF(D7="","",IFERROR(IF(ISNUMBER(SEARCH(Assumptions!$C$5,D7)),Assumptions!$D$5,IF(ISNUMBER(SEARCH(Assumptions!$C$6,D7)),Assumptions!$D$6,IF(ISNUMBER(SEARCH(Assumptions!$C$7,D7)),Assumptions!$D$7,"Other Services"))),"Other Services")) -> Development
A8: 46130 | B8: Almoudi Group Tabuk ST | C8: Development Retainer - Monthly - Almoudi | D8: Development Retainer - Monthly | E8: 8015.74 | F8: 233.66 | G8: 7782.08 | H8: AED | I8: Paid | J8: =IF(D8="","",IFERROR(IF(ISNUMBER(SEARCH(Assumptions!$C$5,D8)),Assumptions!$D$5,IF(ISNUMBER(SEARCH(Assumptions!$C$6,D8)),Assumptions!$D$6,IF(ISNUMBER(SEARCH(Assumptions!$C$7,D8)),Assumptions!$D$7,"Other Services"))),"Other Services")) -> Development
A9: 46137 | B9: Growth X Ventures LLC | C9: WhatsApp API - Monthly Usage - Growth | D9: WhatsApp API - Monthly Usage | E9: 14660.09 | F9: 426.34 | G9: 14233.75 | H9: AED | I9: Paid | J9: =IF(D9="","",IFERROR(IF(ISNUMBER(SEARCH(Assumptions!$C$5,D9)),Assumptions!$D$5,IF(ISNUMBER(SEARCH(Assumptions!$C$6,D9)),Assumptions!$D$6,IF(ISNUMBER(SEARCH(Assumptions!$C$7,D9)),Assumptions!$D$7,"Other Services"))),"Other Services")) -> WhatsApp
A10: 46117 | B10: I Farmer Pte Ltd | C10: Subscription - Pro Plan - I | D10: Subscription - Pro Plan | E10: 4503.4 | F10: 131.8 | G10: 4371.6 | H10: AED | I10: Paid | J10: =IF(D10="","",IFERROR(IF(ISNUMBER(SEARCH(Assumptions!$C$5,D10)),Assumptions!$D$5,IF(ISNUMBER(SEARCH(Assumptions!$C$6,D10)),Assumptions!$D$6,IF(ISNUMBER(SEARCH(Assumptions!$C$7,D10)),Assumptions!$D$7,"Other Services"))),"Other Services")) -> Subscription
A11: 46125 | B11: United Homeware Company (Nice) | C11: WhatsApp API - Monthly Usage - United | D11: WhatsApp API - Monthly Usage | E11: 2463.52 | F11: 72.64 | G11: 2390.88 | H11: AED | I11: Paid | J11: =IF(D11="","",IFERROR(IF(ISNUMBER(SEARCH(Assumptions!$C$5,D11)),Assumptions!$D$5,IF(ISNUMBER(SEARCH(Assumptions!$C$6,D11)),Assumptions!$D$6,IF(ISNUMBER(SEARCH(Assumptions!$C$7,D11)),Assumptions!$D$7,"Other Services"))),"Other Services")) -> WhatsApp
A12: 46138 | B12: Nishat Linen UAE | C12: Subscription - Pro Plan - Nishat | D12: Subscription - Pro Plan | E12: 1547.35 | F12: 46.07 | G12: 1501.28 | H12: AED | I12: Paid | J12: =IF(D12="","",IFERROR(IF(ISNUMBER(SEARCH(Assumptions!$C$5,D12)),Assumptions!$D$5,IF(ISNUMBER(SEARCH(Assumptions!$C$6,D12)),Assumptions!$D$6,IF(ISNUMBER(SEARCH(Assumptions!$C$7,D12)),Assumptions!$D$7,"Other Services"))),"Other Services")) -> Subscription
A13: 46115 | B13: United Homeware Company (Nice) | C13: Subscription - Enterprise Plan - United | D13: Subscription - Enterprise Plan | E13: 10295.1 | F13: 299.76 | G13: 9995.34 | H13: AED | I13: Paid | J13: =IF(D13="","",IFERROR(IF(ISNUMBER(SEARCH(Assumptions!$C$5,D13)),Assumptions!$D$5,IF(ISNUMBER(SEARCH(Assumptions!$C$6,D13)),Assumptions!$D$6,IF(ISNUMBER(SEARCH(Assumptions!$C$7,D13)),Assumptions!$D$7,"Other Services"))),"Other Services")) -> Subscription
A14: 46131 | B14: Nishat Linen UAE | C14: Subscription - Pro Plan - Nishat | D14: Subscription - Pro Plan | E14: 4107.36 | F14: 120.31 | G14: 3987.05 | H14: AED | I14: Paid | J14: =IF(D14="","",IFERROR(IF(ISNUMBER(SEARCH(Assumptions!$C$5,D14)),Assumptions!$D$5,IF(ISNUMBER(SEARCH(Assumptions!$C$6,D14)),Assumptions!$D$6,IF(ISNUMBER(SEARCH(Assumptions!$C$7,D14)),Assumptions!$D$7,"Other Services"))),"Other Services")) -> Subscription
A15: 46137 | B15: Almoudi Group Tabuk ST | C15: WhatsApp Business Platform Fee - Almoudi | D15: WhatsApp Business Platform Fee | E15: 5777.47 | F15: 168.75 | G15: 5608.72 | H15: AED | I15: Paid | J15: =IF(D15="","",IFERROR(IF(ISNUMBER(SEARCH(Assumptions!$C$5,D15)),Assumptions!$D$5,IF(ISNUMBER(SEARCH(Assumptions!$C$6,D15)),Assumptions!$D$6,IF(ISNUMBER(SEARCH(Assumptions!$C$7,D15)),Assumptions!$D$7,"Other Services"))),"Other Services")) -> WhatsApp
A16: 46125 | B16: Merck Serono Middle East FZ-Ltd | C16: WhatsApp API - Monthly Usage - Merck | D16: WhatsApp API - Monthly Usage | E16: 5581.15 | F16: 163.05 | G16: 5418.1 | H16: AED | I16: Paid | J16: =IF(D16="","",IFERROR(IF(ISNUMBER(SEARCH(Assumptions!$C$5,D16)),Assumptions!$D$5,IF(ISNUMBER(SEARCH(Assumptions!$C$6,D16)),Assumptions!$D$6,IF(ISNUMBER(SEARCH(Assumptions!$C$7,D16)),Assumptions!$D$7,"Other Services"))),"Other Services")) -> WhatsApp
... A57: 46180 | B57: I Farmer Pte Ltd | C57: Meta Ad Spend Recovery - Jun-2026 | D57: Meta Ad Spend Recovery | E57: 1050.14 | F57: 31.65 | G57: 1018.49 | H57: AED | I57: Paid | J57: =IF(D57="","",IFERROR(IF(ISNUMBER(SEARCH(Assumptions!$C$5,D57)),Assumptions!$D$5,IF(ISNUMBER(SEARCH(Assumptions!$C$6,D57)),Assumptions!$D$6,IF(ISNUMBER(SEARCH(Assumptions!$C$7,D57)),Assumptions!$D$7,"Other Services"))),"Other Services")) -> Other Services
J58: =IF(D58="","",IFERROR(IF(ISNUMBER(SEARCH(Assumptions!$C$5,D58)),Assumptions!$D$5,IF(ISNUMBER(SEARCH(Assumptions!$C$6,D58)),Assumptions!$D$6,IF(ISNUMBER(SEARCH(Assumptions!$C$7,D58)),Assumptions!$D$7,"Other Services"))),"Other Services"))
J59: =IF(D59="","",IFERROR(IF(ISNUMBER(SEARCH(Assumptions!$C$5,D59)),Assumptions!$D$5,IF(ISNUMBER(SEARCH(Assumptions!$C$6,D59)),Assumptions!$D$6,IF(ISNUMBER(SEARCH(Assumptions!$C$7,D59)),Assumptions!$D$7,"Other Services"))),"Other Services"))
J60: =IF(D60="","",IFERROR(IF(ISNUMBER(SEARCH(Assumptions!$C$5,D60)),Assumptions!$D$5,IF(ISNUMBER(SEARCH(Assumptions!$C$6,D60)),Assumptions!$D$6,IF(ISNUMBER(SEARCH(Assumptions!$C$7,D60)),Assumptions!$D$7,"Other Services"))),"Other Services"))
J61: =IF(D61="","",IFERROR(IF(ISNUMBER(SEARCH(Assumptions!$C$5,D61)),Assumptions!$D$5,IF(ISNUMBER(SEARCH(Assumptions!$C$6,D61)),Assumptions!$D$6,IF(ISNUMBER(SEARCH(Assumptions!$C$7,D61)),Assumptions!$D$7,"Other Services"))),"Other Services"))
J62: =IF(D62="","",IFERROR(IF(ISNUMBER(SEARCH(Assumptions!$C$5,D62)),Assumptions!$D$5,IF(ISNUMBER(SEARCH(Assumptions!$C$6,D62)),Assumptions!$D$6,IF(ISNUMBER(SEARCH(Assumptions!$C$7,D62)),Assumptions!$D$7,"Other Services"))),"Other Services"))
J63: =IF(D63="","",IFERROR(IF(ISNUMBER(SEARCH(Assumptions!$C$5,D63)),Assumptions!$D$5,IF(ISNUMBER(SEARCH(Assumptions!$C$6,D63)),Assumptions!$D$6,IF(ISNUMBER(SEARCH(Assumptions!$C$7,D63)),Assumptions!$D$7,"Other Services"))),"Other Services"))
J64: =IF(D64="","",IFERROR(IF(ISNUMBER(SEARCH(Assumptions!$C$5,D64)),Assumptions!$D$5,IF(ISNUMBER(SEARCH(Assumptions!$C$6,D64)),Assumptions!$D$6,IF(ISNUMBER(SEARCH(Assumptions!$C$7,D64)),Assumptions!$D$7,"Other Services"))),"Other Services"))
J65: =IF(D65="","",IFERROR(IF(ISNUMBER(SEARCH(Assumptions!$C$5,D65)),Assumptions!$D$5,IF(ISNUMBER(SEARCH(Assumptions!$C$6,D65)),Assumptions!$D$6,IF(ISNUMBER(SEARCH(Assumptions!$C$7,D65)),Assumptions!$D$7,"Other Services"))),"Other Services"))
J66: =IF(D66="","",IFERROR(IF(ISNUMBER(SEARCH(Assumptions!$C$5,D66)),Assumptions!$D$5,IF(ISNUMBER(SEARCH(Assumptions!$C$6,D66)),Assumptions!$D$6,IF(ISNUMBER(SEARCH(Assumptions!$C$7,D66)),Assumptions!$D$7,"Other Services"))),"Other Services"))
J67: =IF(D67="","",IFERROR(IF(ISNUMBER(SEARCH(Assumptions!$C$5,D67)),Assumptions!$D$5,IF(ISNUMBER(SEARCH(Assumptions!$C$6,D67)),Assumptions!$D$6,IF(ISNUMBER(SEARCH(Assumptions!$C$7,D67)),Assumptions!$D$7,"Other Services"))),"Other Services"))
J68: =IF(D68="","",IFERROR(IF(ISNUMBER(SEARCH(Assumptions!$C$5,D68)),Assumptions!$D$5,IF(ISNUMBER(SEARCH(Assumptions!$C$6,D68)),Assumptions!$D$6,IF(ISNUMBER(SEARCH(Assumptions!$C$7,D68)),Assumptions!$D$7,"Other Services"))),"Other Services"))
J69: =IF(D69="","",IFERROR(IF(ISNUMBER(SEARCH(Assumptions!$C$5,D69)),Assumptions!$D$5,IF(ISNUMBER(SEARCH(Assumptions!$C$6,D69)),Assumptions!$D$6,IF(ISNUMBER(SEARCH(Assumptions!$C$7,D69)),Assumptions!$D$7,"Other Services"))),"Other Services"))
... J5003: =IF(D5003="","",IFERROR(IF(ISNUMBER(SEARCH(Assumptions!$C$5,D5003)),Assumptions!$D$5,IF(ISNUMBER(SEARCH(Assumptions!$C$6,D5003)),Assumptions!$D$6,IF(ISNUMBER(SEARCH(Assumptions!$C$7,D5003)),Assumptions!$D$7,"Other Services"))),"Other Services"))

Sheet Xero_Raw
A1: XERO — RAW LEDGER EXPORT (Invoices + Bills, paste your Xero export below, starting row 4)
A2: Source: Xero > Business > Invoices/Bills > Export, or Power Query (see README_Setup). Type = "Invoice" (AR/Sales) or "Bill" (AP/Expense). This tab is pre-formulated for up to 5,000 rows (through row 5003) — just paste your data starting row 4.
A3: Date | B3: Due Date | C3: Type | D3: Contact | E3: Country (auto) | F3: Account/Line Item | G3: Description | H3: Amount (AED) | I3: Status | J3: Category (auto)
A4: 46115 | B4: 46145 | C4: Invoice | D4: Al Fardan Exchange - Sole Proprietorship L.L.C | E4: =IFERROR(VLOOKUP(D4,Assumptions!$G$5:$H$16,2,0),"Other") -> UAE | F4: Subscription - Pro Plan | G4: Subscription - Pro Plan - Apr-2026 | H4: 31821.05 | I4: Draft | J4: =IFERROR(IF(ISNUMBER(SEARCH(Assumptions!$C$5,G4)),Assumptions!$D$5,IF(ISNUMBER(SEARCH(Assumptions!$C$6,G4)),Assumptions!$D$6,IF(ISNUMBER(SEARCH(Assumptions!$C$7,G4)),Assumptions!$D$7,"Other Services"))),"Other Services") -> Subscription
A5: 46130 | B5: 46160 | C5: Invoice | D5: Curahealth K.S.C.C. | E5: =IF(D5="","",IFERROR(VLOOKUP(D5,Assumptions!$G$5:$H$16,2,0),"Other")) -> Kuwait | F5: WhatsApp Business Platform Fee | G5: WhatsApp Business Platform Fee - Apr-2026 | H5: 9674.09 | I5: Draft | J5: =IF(G5="","",IFERROR(IF(ISNUMBER(SEARCH(Assumptions!$C$5,G5)),Assumptions!$D$5,IF(ISNUMBER(SEARCH(Assumptions!$C$6,G5)),Assumptions!$D$6,IF(ISNUMBER(SEARCH(Assumptions!$C$7,G5)),Assumptions!$D$7,"Other Services"))),"Other Services")) -> WhatsApp
A6: 46128 | B6: 46158 | C6: Invoice | D6: Nishat Linen UAE | E6: =IF(D6="","",IFERROR(VLOOKUP(D6,Assumptions!$G$5:$H$16,2,0),"Other")) -> UAE | F6: Custom Development - Sprint Invoice | G6: Custom Development - Sprint Invoice - Apr-2026 | H6: 16093.84 | I6: Void | J6: =IF(G6="","",IFERROR(IF(ISNUMBER(SEARCH(Assumptions!$C$5,G6)),Assumptions!$D$5,IF(ISNUMBER(SEARCH(Assumptions!$C$6,G6)),Assumptions!$D$6,IF(ISNUMBER(SEARCH(Assumptions!$C$7,G6)),Assumptions!$D$7,"Other Services"))),"Other Services")) -> Development
A7: 46116 | B7: 46146 | C7: Invoice | D7: Misfit Technologies Pte Ltd | E7: =IF(D7="","",IFERROR(VLOOKUP(D7,Assumptions!$G$5:$H$16,2,0),"Other")) -> Singapore | F7: WhatsApp Business Platform Fee | G7: WhatsApp Business Platform Fee - Apr-2026 | H7: 7621.99 | I7: Void | J7: =IF(G7="","",IFERROR(IF(ISNUMBER(SEARCH(Assumptions!$C$5,G7)),Assumptions!$D$5,IF(ISNUMBER(SEARCH(Assumptions!$C$6,G7)),Assumptions!$D$6,IF(ISNUMBER(SEARCH(Assumptions!$C$7,G7)),Assumptions!$D$7,"Other Services"))),"Other Services")) -> WhatsApp
A8: 46127 | B8: 46157 | C8: Invoice | D8: Misfit Technologies Pte Ltd | E8: =IF(D8="","",IFERROR(VLOOKUP(D8,Assumptions!$G$5:$H$16,2,0),"Other")) -> Singapore | F8: Subscription - Enterprise Plan | G8: Subscription - Enterprise Plan - Apr-2026 | H8: 52102.53 | I8: Unsent | J8: =IF(G8="","",IFERROR(IF(ISNUMBER(SEARCH(Assumptions!$C$5,G8)),Assumptions!$D$5,IF(ISNUMBER(SEARCH(Assumptions!$C$6,G8)),Assumptions!$D$6,IF(ISNUMBER(SEARCH(Assumptions!$C$7,G8)),Assumptions!$D$7,"Other Services"))),"Other Services")) -> Subscription
A9: 46116 | B9: 46146 | C9: Invoice | D9: Almoudi Group Tabuk ST | E9: =IF(D9="","",IFERROR(VLOOKUP(D9,Assumptions!$G$5:$H$16,2,0),"Other")) -> Saudi Arabia | F9: Development Retainer - Monthly | G9: Development Retainer - Monthly - Apr-2026 | H9: 5515.54 | I9: Unsent | J9: =IF(G9="","",IFERROR(IF(ISNUMBER(SEARCH(Assumptions!$C$5,G9)),Assumptions!$D$5,IF(ISNUMBER(SEARCH(Assumptions!$C$6,G9)),Assumptions!$D$6,IF(ISNUMBER(SEARCH(Assumptions!$C$7,G9)),Assumptions!$D$7,"Other Services"))),"Other Services")) -> Development
A10: 46119 | B10: 46149 | C10: Invoice | D10: United Homeware Company (Nice) | E10: =IF(D10="","",IFERROR(VLOOKUP(D10,Assumptions!$G$5:$H$16,2,0),"Other")) -> UAE | F10: WhatsApp Business Platform Fee | G10: WhatsApp Business Platform Fee - Apr-2026 | H10: 13032.12 | I10: Draft | J10: =IF(G10="","",IFERROR(IF(ISNUMBER(SEARCH(Assumptions!$C$5,G10)),Assumptions!$D$5,IF(ISNUMBER(SEARCH(Assumptions!$C$6,G10)),Assumptions!$D$6,IF(ISNUMBER(SEARCH(Assumptions!$C$7,G10)),Assumptions!$D$7,"Other Services"))),"Other Services")) -> WhatsApp
A11: 46121 | B11: 46151 | C11: Invoice | D11: Misfit Technologies Pte Ltd | E11: =IF(D11="","",IFERROR(VLOOKUP(D11,Assumptions!$G$5:$H$16,2,0),"Other")) -> Singapore | F11: WhatsApp Business Platform Fee | G11: WhatsApp Business Platform Fee - Apr-2026 | H11: 28832.43 | I11: Void | J11: =IF(G11="","",IFERROR(IF(ISNUMBER(SEARCH(Assumptions!$C$5,G11)),Assumptions!$D$5,IF(ISNUMBER(SEARCH(Assumptions!$C$6,G11)),Assumptions!$D$6,IF(ISNUMBER(SEARCH(Assumptions!$C$7,G11)),Assumptions!$D$7,"Other Services"))),"Other Services")) -> WhatsApp
A12: 46127 | B12: 46127 | C12: Bill | D12: Salary - General & Administration | E12: =IF(D12="","",IFERROR(VLOOKUP(D12,Assumptions!$G$5:$H$16,2,0),"Other")) -> Other | F12: Salary - General & Administration | G12: Salary - General & Administration - Apr-2026 | H12: 20296.54 | I12: Paid | J12: =IF(G12="","",IFERROR(IF(ISNUMBER(SEARCH(Assumptions!$C$5,G12)),Assumptions!$D$5,IF(ISNUMBER(SEARCH(Assumptions!$C$6,G12)),Assumptions!$D$6,IF(ISNUMBER(SEARCH(Assumptions!$C$7,G12)),Assumptions!$D$7,"Other Services"))),"Other Services")) -> Other Services
A13: 46116 | B13: 46116 | C13: Bill | D13: Travel Expense | E13: =IF(D13="","",IFERROR(VLOOKUP(D13,Assumptions!$G$5:$H$16,2,0),"Other")) -> Other | F13: Travel Expense | G13: Travel Expense - Apr-2026 | H13: 1739.41 | I13: Paid | J13: =IF(G13="","",IFERROR(IF(ISNUMBER(SEARCH(Assumptions!$C$5,G13)),Assumptions!$D$5,IF(ISNUMBER(SEARCH(Assumptions!$C$6,G13)),Assumptions!$D$6,IF(ISNUMBER(SEARCH(Assumptions!$C$7,G13)),Assumptions!$D$7,"Other Services"))),"Other Services")) -> Other Services
A14: 46113 | B14: 46113 | C14: Bill | D14: Travel Expense | E14: =IF(D14="","",IFERROR(VLOOKUP(D14,Assumptions!$G$5:$H$16,2,0),"Other")) -> Other | F14: Travel Expense | G14: Travel Expense - Apr-2026 | H14: 24240.41 | I14: Paid | J14: =IF(G14="","",IFERROR(IF(ISNUMBER(SEARCH(Assumptions!$C$5,G14)),Assumptions!$D$5,IF(ISNUMBER(SEARCH(Assumptions!$C$6,G14)),Assumptions!$D$6,IF(ISNUMBER(SEARCH(Assumptions!$C$7,G14)),Assumptions!$D$7,"Other Services"))),"Other Services")) -> Other Services
A15: 46118 | B15: 46118 | C15: Bill | D15: Office Rent | E15: =IF(D15="","",IFERROR(VLOOKUP(D15,Assumptions!$G$5:$H$16,2,0),"Other")) -> Other | F15: Office Rent | G15: Office Rent - Apr-2026 | H15: 10457.14 | I15: Paid | J15: =IF(G15="","",IFERROR(IF(ISNUMBER(SEARCH(Assumptions!$C$5,G15)),Assumptions!$D$5,IF(ISNUMBER(SEARCH(Assumptions!$C$6,G15)),Assumptions!$D$6,IF(ISNUMBER(SEARCH(Assumptions!$C$7,G15)),Assumptions!$D$7,"Other Services"))),"Other Services")) -> Other Services
A16: 46119 | B16: 46119 | C16: Bill | D16: Trade License Fee | E16: =IF(D16="","",IFERROR(VLOOKUP(D16,Assumptions!$G$5:$H$16,2,0),"Other")) -> Other | F16: Trade License Fee | G16: Trade License Fee - Apr-2026 | H16: 21683.93 | I16: Paid | J16: =IF(G16="","",IFERROR(IF(ISNUMBER(SEARCH(Assumptions!$C$5,G16)),Assumptions!$D$5,IF(ISNUMBER(SEARCH(Assumptions!$C$6,G16)),Assumptions!$D$6,IF(ISNUMBER(SEARCH(Assumptions!$C$7,G16)),Assumptions!$D$7,"Other Services"))),"Other Services")) -> Other Services
... A42: 46197 | B42: 46197 | C42: Bill | D42: Office Rent | E42: =IF(D42="","",IFERROR(VLOOKUP(D42,Assumptions!$G$5:$H$16,2,0),"Other")) -> Other | F42: Office Rent | G42: Office Rent - Jun-2026 | H42: 11324.97 | I42: Paid | J42: =IF(G42="","",IFERROR(IF(ISNUMBER(SEARCH(Assumptions!$C$5,G42)),Assumptions!$D$5,IF(ISNUMBER(SEARCH(Assumptions!$C$6,G42)),Assumptions!$D$6,IF(ISNUMBER(SEARCH(Assumptions!$C$7,G42)),Assumptions!$D$7,"Other Services"))),"Other Services")) -> Other Services
E43: =IF(D43="","",IFERROR(VLOOKUP(D43,Assumptions!$G$5:$H$16,2,0),"Other")) | J43: =IF(G43="","",IFERROR(IF(ISNUMBER(SEARCH(Assumptions!$C$5,G43)),Assumptions!$D$5,IF(ISNUMBER(SEARCH(Assumptions!$C$6,G43)),Assumptions!$D$6,IF(ISNUMBER(SEARCH(Assumptions!$C$7,G43)),Assumptions!$D$7,"Other Services"))),"Other Services"))
E44: =IF(D44="","",IFERROR(VLOOKUP(D44,Assumptions!$G$5:$H$16,2,0),"Other")) | J44: =IF(G44="","",IFERROR(IF(ISNUMBER(SEARCH(Assumptions!$C$5,G44)),Assumptions!$D$5,IF(ISNUMBER(SEARCH(Assumptions!$C$6,G44)),Assumptions!$D$6,IF(ISNUMBER(SEARCH(Assumptions!$C$7,G44)),Assumptions!$D$7,"Other Services"))),"Other Services"))
E45: =IF(D45="","",IFERROR(VLOOKUP(D45,Assumptions!$G$5:$H$16,2,0),"Other")) | J45: =IF(G45="","",IFERROR(IF(ISNUMBER(SEARCH(Assumptions!$C$5,G45)),Assumptions!$D$5,IF(ISNUMBER(SEARCH(Assumptions!$C$6,G45)),Assumptions!$D$6,IF(ISNUMBER(SEARCH(Assumptions!$C$7,G45)),Assumptions!$D$7,"Other Services"))),"Other Services"))
E46: =IF(D46="","",IFERROR(VLOOKUP(D46,Assumptions!$G$5:$H$16,2,0),"Other")) | J46: =IF(G46="","",IFERROR(IF(ISNUMBER(SEARCH(Assumptions!$C$5,G46)),Assumptions!$D$5,IF(ISNUMBER(SEARCH(Assumptions!$C$6,G46)),Assumptions!$D$6,IF(ISNUMBER(SEARCH(Assumptions!$C$7,G46)),Assumptions!$D$7,"Other Services"))),"Other Services"))
E47: =IF(D47="","",IFERROR(VLOOKUP(D47,Assumptions!$G$5:$H$16,2,0),"Other")) | J47: =IF(G47="","",IFERROR(IF(ISNUMBER(SEARCH(Assumptions!$C$5,G47)),Assumptions!$D$5,IF(ISNUMBER(SEARCH(Assumptions!$C$6,G47)),Assumptions!$D$6,IF(ISNUMBER(SEARCH(Assumptions!$C$7,G47)),Assumptions!$D$7,"Other Services"))),"Other Services"))
E48: =IF(D48="","",IFERROR(VLOOKUP(D48,Assumptions!$G$5:$H$16,2,0),"Other")) | J48: =IF(G48="","",IFERROR(IF(ISNUMBER(SEARCH(Assumptions!$C$5,G48)),Assumptions!$D$5,IF(ISNUMBER(SEARCH(Assumptions!$C$6,G48)),Assumptions!$D$6,IF(ISNUMBER(SEARCH(Assumptions!$C$7,G48)),Assumptions!$D$7,"Other Services"))),"Other Services"))
E49: =IF(D49="","",IFERROR(VLOOKUP(D49,Assumptions!$G$5:$H$16,2,0),"Other")) | J49: =IF(G49="","",IFERROR(IF(ISNUMBER(SEARCH(Assumptions!$C$5,G49)),Assumptions!$D$5,IF(ISNUMBER(SEARCH(Assumptions!$C$6,G49)),Assumptions!$D$6,IF(ISNUMBER(SEARCH(Assumptions!$C$7,G49)),Assumptions!$D$7,"Other Services"))),"Other Services"))
E50: =IF(D50="","",IFERROR(VLOOKUP(D50,Assumptions!$G$5:$H$16,2,0),"Other")) | J50: =IF(G50="","",IFERROR(IF(ISNUMBER(SEARCH(Assumptions!$C$5,G50)),Assumptions!$D$5,IF(ISNUMBER(SEARCH(Assumptions!$C$6,G50)),Assumptions!$D$6,IF(ISNUMBER(SEARCH(Assumptions!$C$7,G50)),Assumptions!$D$7,"Other Services"))),"Other Services"))
E51: =IF(D51="","",IFERROR(VLOOKUP(D51,Assumptions!$G$5:$H$16,2,0),"Other")) | J51: =IF(G51="","",IFERROR(IF(ISNUMBER(SEARCH(Assumptions!$C$5,G51)),Assumptions!$D$5,IF(ISNUMBER(SEARCH(Assumptions!$C$6,G51)),Assumptions!$D$6,IF(ISNUMBER(SEARCH(Assumptions!$C$7,G51)),Assumptions!$D$7,"Other Services"))),"Other Services"))
E52: =IF(D52="","",IFERROR(VLOOKUP(D52,Assumptions!$G$5:$H$16,2,0),"Other")) | J52: =IF(G52="","",IFERROR(IF(ISNUMBER(SEARCH(Assumptions!$C$5,G52)),Assumptions!$D$5,IF(ISNUMBER(SEARCH(Assumptions!$C$6,G52)),Assumptions!$D$6,IF(ISNUMBER(SEARCH(Assumptions!$C$7,G52)),Assumptions!$D$7,"Other Services"))),"Other Services"))
E53: =IF(D53="","",IFERROR(VLOOKUP(D53,Assumptions!$G$5:$H$16,2,0),"Other")) | J53: =IF(G53="","",IFERROR(IF(ISNUMBER(SEARCH(Assumptions!$C$5,G53)),Assumptions!$D$5,IF(ISNUMBER(SEARCH(Assumptions!$C$6,G53)),Assumptions!$D$6,IF(ISNUMBER(SEARCH(Assumptions!$C$7,G53)),Assumptions!$D$7,"Other Services"))),"Other Services"))
E54: =IF(D54="","",IFERROR(VLOOKUP(D54,Assumptions!$G$5:$H$16,2,0),"Other")) | J54: =IF(G54="","",IFERROR(IF(ISNUMBER(SEARCH(Assumptions!$C$5,G54)),Assumptions!$D$5,IF(ISNUMBER(SEARCH(Assumptions!$C$6,G54)),Assumptions!$D$6,IF(ISNUMBER(SEARCH(Assumptions!$C$7,G54)),Assumptions!$D$7,"Other Services"))),"Other Services"))
... E5003: =IF(D5003="","",IFERROR(VLOOKUP(D5003,Assumptions!$G$5:$H$16,2,0),"Other")) | J5003: =IF(G5003="","",IFERROR(IF(ISNUMBER(SEARCH(Assumptions!$C$5,G5003)),Assumptions!$D$5,IF(ISNUMBER(SEARCH(Assumptions!$C$6,G5003)),Assumptions!$D$6,IF(ISNUMBER(SEARCH(Assumptions!$C$7,G5003)),Assumptions!$D$7,"Other Services"))),"Other Services"))

Sheet Bank_Raw
A1: BANK STATEMENT — RAW EXPORT (paste your bank statement CSV/PDF-extracted lines below, starting row 4)
A2: Source: Wio Bank / bank portal statement export. Used for cash position reconciliation on Dashboard. This tab is pre-sized for up to 5,000 rows (through row 5003).
A3: Date | B3: Account | C3: Description | D3: Money In (AED) | E3: Money Out (AED) | F3: Balance (AED) | G3: Customer (if applicable — tag receipts that recover Meta ad spend)
A4: 46116 | B4: Wio Bank PJSC - 650 (USD) | C4: Salary run | D4: 0 | E4: 2681.54 | F4: 247318.46
A5: 46119 | B5: Wio Bank PJSC - 451 (AED) | C5: Salary run | D5: 0 | E5: 11858.94 | F5: 235459.52
A6: 46121 | B6: Wio Bank PJSC - 451 (AED) | C6: Customer receipt - Meta ad spend recovery | D6: 15221.41 | E6: 0 | F6: 250680.93 | G6: Growth X Ventures LLC
A7: 46122 | B7: Wio Bank PJSC - 650 (USD) | C7: Customer receipt - Meta ad spend recovery | D7: 10731.66 | E7: 0 | F7: 261412.59 | G7: United Homeware Company (Nice)
A8: 46123 | B8: Wio Bank PJSC - 650 (USD) | C8: SaaS subscription | D8: 0 | E8: 17740.63 | F8: 243671.96
A9: 46126 | B9: Wio Bank PJSC - 451 (AED) | C9: Salary run | D9: 0 | E9: 5116.38 | F9: 238555.58
A10: 46127 | B10: Wio Bank PJSC - 650 (USD) | C10: Customer receipt - Meta ad spend recovery | D10: 29726.01 | E10: 0 | F10: 268281.59 | G10: Growth X Ventures LLC
A11: 46129 | B11: Wio Bank PJSC - 650 (USD) | C11: Salary run | D11: 0 | E11: 17349.25 | F11: 250932.34
A12: 46131 | B12: Wio Bank PJSC - 451 (AED) | C12: Meta Ads payment | D12: 0 | E12: 2607.86 | F12: 248324.48
A13: 46133 | B13: Wio Bank PJSC - 451 (AED) | C13: Customer receipt | D13: 36819.62 | E13: 0 | F13: 285144.1
A14: 46135 | B14: Wio Bank PJSC - 650 (USD) | C14: Salary run | D14: 0 | E14: 17490.8 | F14: 267653.3
A15: 46136 | B15: Wio Bank PJSC - 451 (AED) | C15: Customer receipt | D15: 11865.52 | E15: 0 | F15: 279518.82
A16: 46137 | B16: Wio Bank PJSC - 650 (USD) | C16: Customer receipt | D16: 20866.82 | E16: 0 | F16: 300385.64
A17: 46140 | B17: Wio Bank PJSC - 650 (USD) | C17: Office rent | D17: 0 | E17: 2749.16 | F17: 297636.48
A18: 46141 | B18: Wio Bank PJSC - 650 (USD) | C18: Customer receipt | D18: 24266.28 | E18: 0 | F18: 321902.76
A19: 46143 | B19: Wio Bank PJSC - 650 (USD) | C19: Customer receipt | D19: 39385.2 | E19: 0 | F19: 361287.96
A20: 46144 | B20: Wio Bank PJSC - 650 (USD) | C20: Meta Ads payment | D20: 0 | E20: 4206.54 | F20: 357081.42
A21: 46147 | B21: Wio Bank PJSC - 650 (USD) | C21: Customer receipt | D21: 37097.43 | E21: 0 | F21: 394178.85
A22: 46150 | B22: Wio Bank PJSC - 451 (AED) | C22: Customer receipt | D22: 3728.98 | E22: 0 | F22: 397907.83
... A44: 46201 | B44: Wio Bank PJSC - 451 (AED) | C44: Customer receipt | D44: 10019.2 | E44: 0 | F44: 499639.33

Sheet Meta_Invoices
A1: META (FACEBOOK/INSTAGRAM ADS) — MONTHLY INVOICE DETAIL, RE-CHARGED TO CUSTOMERS
A2: Each Meta PDF invoice bundles multiple customer ad accounts. Enter one row per customer/campaign line as shown on the PDF. Meta shows "Amount Charged" NET of any coupon/discount applied — Gross Amount below ADDS the discount back, so the single Gross figure reflects the true ad spend value delivered per customer before any Meta promo credit. This tab is pre-sized for up to 5,000 rows (through row 5003).
A3: Invoice Date | B3: Invoice No. | C3: Month | D3: Customer | E3: Ad Account ID | F3: Campaign | G3: Amount Charged (Net, AED) | H3: Discount / Coupon Applied (AED) | I3: Gross Amount (Charged+Discount) (AED) | J3: Currency | K3: Notes
A4: 46115 | B4: META-100231 | C4: =TEXT(A4,"mmm-yyyy") -> Apr-2026 | D4: Al Fardan Exchange - Sole Proprietorship L.L.C | E4: act_961168 | F4: Prospecting - Reach | G4: 3996.67 | H4: 228.78 | I4: =G4+H4 -> 4225.45 | J4: AED | K4: Coupon applied
A5: 46115 | B5: META-100231 | C5: =IF(A5="","",TEXT(A5,"mmm-yyyy")) -> Apr-2026 | D5: Al Fardan Exchange - Sole Proprietorship L.L.C | E5: act_139317 | F5: Prospecting - Reach | G5: 1726.19 | H5: 217.7 | I5: =IF(G5="","",G5+H5) -> 1943.89 | J5: AED | K5: Coupon applied
A6: 46115 | B6: META-100231 | C6: =IF(A6="","",TEXT(A6,"mmm-yyyy")) -> Apr-2026 | D6: United Homeware Company (Nice) | E6: act_161981 | F6: Prospecting - Reach | G6: 1930.87 | H6: 256.14 | I6: =IF(G6="","",G6+H6) -> 2187.01 | J6: AED | K6: Coupon applied
A7: 46115 | B7: META-100231 | C7: =IF(A7="","",TEXT(A7,"mmm-yyyy")) -> Apr-2026 | D7: United Homeware Company (Nice) | E7: act_711316 | F7: Prospecting - Reach | G7: 3995.05 | H7: 0 | I7: =IF(G7="","",G7+H7) -> 3995.05 | J7: AED
A8: 46115 | B8: META-100231 | C8: =IF(A8="","",TEXT(A8,"mmm-yyyy")) -> Apr-2026 | D8: Growth X Ventures LLC | E8: act_239643 | F8: Brand Awareness | G8: 493.4 | H8: 65.87 | I8: =IF(G8="","",G8+H8) -> 559.27 | J8: AED | K8: Coupon applied
A9: 46115 | B9: META-100231 | C9: =IF(A9="","",TEXT(A9,"mmm-yyyy")) -> Apr-2026 | D9: Growth X Ventures LLC | E9: act_687472 | F9: Retargeting - Conversions | G9: 1934.64 | H9: 262.41 | I9: =IF(G9="","",G9+H9) -> 2197.05 | J9: AED | K9: Coupon applied
A10: 46115 | B10: META-100231 | C10: =IF(A10="","",TEXT(A10,"mmm-yyyy")) -> Apr-2026 | D10: I Farmer Pte Ltd | E10: act_490487 | F10: Prospecting - Reach | G10: 2568.24 | H10: 0 | I10: =IF(G10="","",G10+H10) -> 2568.24 | J10: AED
A11: 46115 | B11: META-100231 | C11: =IF(A11="","",TEXT(A11,"mmm-yyyy")) -> Apr-2026 | D11: Misfit Technologies Pte Ltd | E11: act_620528 | F11: Lead Gen - Lookalike | G11: 2501.04 | H11: 0 | I11: =IF(G11="","",G11+H11) -> 2501.04 | J11: AED
A12: 46115 | B12: META-100231 | C12: =IF(A12="","",TEXT(A12,"mmm-yyyy")) -> Apr-2026 | D12: Nishat Linen UAE | E12: act_479146 | F12: Brand Awareness | G12: 2115.85 | H12: 0 | I12: =IF(G12="","",G12+H12) -> 2115.85 | J12: AED
A13: 46115 | B13: META-100231 | C13: =IF(A13="","",TEXT(A13,"mmm-yyyy")) -> Apr-2026 | D13: Nishat Linen UAE | E13: act_185831 | F13: Brand Awareness | G13: 1268.86 | H13: 211.87 | I13: =IF(G13="","",G13+H13) -> 1480.73 | J13: AED | K13: Coupon applied
A14: 46145 | B14: META-100232 | C14: =IF(A14="","",TEXT(A14,"mmm-yyyy")) -> May-2026 | D14: Al Fardan Exchange - Sole Proprietorship L.L.C | E14: act_401924 | F14: Prospecting - Reach | G14: 3713.04 | H14: 0 | I14: =IF(G14="","",G14+H14) -> 3713.04 | J14: AED
A15: 46145 | B15: META-100232 | C15: =IF(A15="","",TEXT(A15,"mmm-yyyy")) -> May-2026 | D15: Al Fardan Exchange - Sole Proprietorship L.L.C | E15: act_259367 | F15: Lead Gen - Lookalike | G15: 760.46 | H15: 124.39 | I15: =IF(G15="","",G15+H15) -> 884.85 | J15: AED | K15: Coupon applied
A16: 46145 | B16: META-100232 | C16: =IF(A16="","",TEXT(A16,"mmm-yyyy")) -> May-2026 | D16: United Homeware Company (Nice) | E16: act_901710 | F16: Brand Awareness | G16: 452.91 | H16: 0 | I16: =IF(G16="","",G16+H16) -> 452.91 | J16: AED
A17: 46145 | B17: META-100232 | C17: =IF(A17="","",TEXT(A17,"mmm-yyyy")) -> May-2026 | D17: United Homeware Company (Nice) | E17: act_935601 | F17: Lead Gen - Lookalike | G17: 1626.48 | H17: 202.5 | I17: =IF(G17="","",G17+H17) -> 1828.98 | J17: AED | K17: Coupon applied
A18: 46145 | B18: META-100232 | C18: =IF(A18="","",TEXT(A18,"mmm-yyyy")) -> May-2026 | D18: Growth X Ventures LLC | E18: act_597128 | F18: Prospecting - Reach | G18: 3575.87 | H18: 0 | I18: =IF(G18="","",G18+H18) -> 3575.87 | J18: AED
A19: 46145 | B19: META-100232 | C19: =IF(A19="","",TEXT(A19,"mmm-yyyy")) -> May-2026 | D19: I Farmer Pte Ltd | E19: act_814328 | F19: Lead Gen - Lookalike | G19: 3151.52 | H19: 430.79 | I19: =IF(G19="","",G19+H19) -> 3582.31 | J19: AED | K19: Coupon applied
A20: 46145 | B20: META-100232 | C20: =IF(A20="","",TEXT(A20,"mmm-yyyy")) -> May-2026 | D20: Misfit Technologies Pte Ltd | E20: act_463861 | F20: Prospecting - Reach | G20: 3094.85 | H20: 0 | I20: =IF(G20="","",G20+H20) -> 3094.85 | J20: AED
A21: 46145 | B21: META-100232 | C21: =IF(A21="","",TEXT(A21,"mmm-yyyy")) -> May-2026 | D21: Misfit Technologies Pte Ltd | E21: act_617674 | F21: Prospecting - Reach | G21: 3968.53 | H21: 562.09 | I21: =IF(G21="","",G21+H21) -> 4530.62 | J21: AED | K21: Coupon applied
A22: 46145 | B22: META-100232 | C22: =IF(A22="","",TEXT(A22,"mmm-yyyy")) -> May-2026 | D22: Nishat Linen UAE | E22: act_509940 | F22: Lead Gen - Lookalike | G22: 3296.11 | H22: 287.23 | I22: =IF(G22="","",G22+H22) -> 3583.34 | J22: AED | K22: Coupon applied
A23: 46176 | B23: META-100233 | C23: =IF(A23="","",TEXT(A23,"mmm-yyyy")) -> Jun-2026 | D23: Al Fardan Exchange - Sole Proprietorship L.L.C | E23: act_243577 | F23: Lead Gen - Lookalike | G23: 948.83 | H23: 86.98 | I23: =IF(G23="","",G23+H23) -> 1035.81 | J23: AED | K23: Coupon applied
A24: 46176 | B24: META-100233 | C24: =IF(A24="","",TEXT(A24,"mmm-yyyy")) -> Jun-2026 | D24: United Homeware Company (Nice) | E24: act_815887 | F24: Lead Gen - Lookalike | G24: 3054.95 | H24: 0 | I24: =IF(G24="","",G24+H24) -> 3054.95 | J24: AED
A25: 46176 | B25: META-100233 | C25: =IF(A25="","",TEXT(A25,"mmm-yyyy")) -> Jun-2026 | D25: United Homeware Company (Nice) | E25: act_343224 | F25: Retargeting - Conversions | G25: 4035.15 | H25: 308.42 | I25: =IF(G25="","",G25+H25) -> 4343.57 | J25: AED | K25: Coupon applied
A26: 46176 | B26: META-100233 | C26: =IF(A26="","",TEXT(A26,"mmm-yyyy")) -> Jun-2026 | D26: Growth X Ventures LLC | E26: act_375509 | F26: Brand Awareness | G26: 2191.35 | H26: 0 | I26: =IF(G26="","",G26+H26) -> 2191.35 | J26: AED
A27: 46176 | B27: META-100233 | C27: =IF(A27="","",TEXT(A27,"mmm-yyyy")) -> Jun-2026 | D27: I Farmer Pte Ltd | E27: act_434088 | F27: Retargeting - Conversions | G27: 868.14 | H27: 122.82 | I27: =IF(G27="","",G27+H27) -> 990.96 | J27: AED | K27: Coupon applied
A28: 46176 | B28: META-100233 | C28: =IF(A28="","",TEXT(A28,"mmm-yyyy")) -> Jun-2026 | D28: Misfit Technologies Pte Ltd | E28: act_813634 | F28: Lead Gen - Lookalike | G28: 2080.91 | H28: 0 | I28: =IF(G28="","",G28+H28) -> 2080.91 | J28: AED
A29: 46176 | B29: META-100233 | C29: =IF(A29="","",TEXT(A29,"mmm-yyyy")) -> Jun-2026 | D29: Nishat Linen UAE | E29: act_165271 | F29: Retargeting - Conversions | G29: 1856.02 | H29: 269.39 | I29: =IF(G29="","",G29+H29) -> 2125.41 | J29: AED | K29: Coupon applied
A30: 46176 | B30: META-100233 | C30: =IF(A30="","",TEXT(A30,"mmm-yyyy")) -> Jun-2026 | D30: Nishat Linen UAE | E30: act_456572 | F30: Prospecting - Reach | G30: 562.66 | H30: 41.83 | I30: =IF(G30="","",G30+H30) -> 604.49 | J30: AED | K30: Coupon applied
C31: =IF(A31="","",TEXT(A31,"mmm-yyyy")) | I31: =IF(G31="","",G31+H31)
C32: =IF(A32="","",TEXT(A32,"mmm-yyyy")) | I32: =IF(G32="","",G32+H32)
C33: =IF(A33="","",TEXT(A33,"mmm-yyyy")) | I33: =IF(G33="","",G33+H33)
C34: =IF(A34="","",TEXT(A34,"mmm-yyyy")) | I34: =IF(G34="","",G34+H34)
C35: =IF(A35="","",TEXT(A35,"mmm-yyyy")) | I35: =IF(G35="","",G35+H35)
C36: =IF(A36="","",TEXT(A36,"mmm-yyyy")) | I36: =IF(G36="","",G36+H36)
C37: =IF(A37="","",TEXT(A37,"mmm-yyyy")) | I37: =IF(G37="","",G37+H37)
C38: =IF(A38="","",TEXT(A38,"mmm-yyyy")) | I38: =IF(G38="","",G38+H38)
C39: =IF(A39="","",TEXT(A39,"mmm-yyyy")) | I39: =IF(G39="","",G39+H39)
C40: =IF(A40="","",TEXT(A40,"mmm-yyyy")) | I40: =IF(G40="","",G40+H40)
...

Sheet Assumptions
A1: ASSUMPTIONS & MAPPING TABLES — EDIT THESE (BLUE) TO RECLASSIFY DATA ACROSS THE WHOLE DASHBOARD
B3: REVENUE CATEGORY KEYWORD MAP | G3: CUSTOMER → COUNTRY MAP (drives UAE / Singapore / Other split on Receivables tab)
B4: # | C4: Keyword (searched in Description, not case-sensitive) | D4: Maps to Category | G4: Customer / Contact Name | H4: Country
B5: 1 | C5: whatsapp | D5: WhatsApp | G5: Al Fardan Exchange - Sole Proprietorship L.L.C | H5: UAE
B6: 2 | C6: subscription | D6: Subscription | G6: United Homeware Company (Nice) | H6: UAE
B7: 3 | C7: development | D7: Development | G7: Jarir Bookstore | H7: Saudi Arabia
G8: Merck Serono Middle East FZ-Ltd | H8: UAE
B9: Note: rows 5-7 are referenced directly by formulas in Stripe_Raw!J and Xero_Raw!J. To add a 4th category, extend the formula in those sheets. | G9: Growth X Ventures LLC | H9: UAE
G10: I Farmer Pte Ltd | H10: Singapore
G11: Misfit Technologies Pte Ltd | H11: Singapore
G12: Curahealth K.S.C.C. | H12: Kuwait
G13: Ticket Wala | H13: Pakistan
G14: Nishat Linen UAE | H14: UAE
G15: Almoudi Group Tabuk ST | H15: Saudi Arabia
G16: Faysal Bank | H16: Pakistan
G18: Add new rows here as new customers/contacts appear in Xero — VLOOKUP range is $G$5:$H$16, extend if needed.
B22: COLOR LEGEND
B23: Blue text | C23: Hardcoded input — raw data pasted from Stripe/Xero/bank/Meta exports, or editable assumptions
B24: Black text | C24: Formula / calculation
B25: Green text | C25: Link pulling from another sheet in this workbook
B26: Yellow fill | C26: Key assumption cell — review/update before relying on outputs
B29: GENERAL ASSUMPTIONS
B30: Reporting Currency | C30: AED
B31: AR Aging Buckets (days) | C31: 0-30 / 31-60 / 61-90 / 90+
B32: Dashboard Period | C32: Apr-2026 to Jun-2026 (sample data)

Sheet Credit_Card_Upload
A1: CREDIT CARD STATEMENTS — UPLOAD ZONE
A2: HOW TO USE: 1) Upload your credit card statement (PDF or Excel/CSV) in the chat to Claude and ask it to extract the transactions into this tab — Claude will read the statement and paste the rows below in this exact format. 2) Or paste your own exported transactions manually, keeping the same columns. Category is auto-classified from the Assumptions keyword map; anything unmatched shows "Other Services" — add keywords in Assumptions if needed. This tab is pre-formulated for up to 5,000 rows (through row 5003) — just paste your data starting row 4.
A3: Source File | B3: Statement Period | C3: Transaction Date | D3: Card / Last 4 Digits | E3: Merchant / Description | F3: Amount (AED) | G3: Category (auto)
A4: CC_Statement_Apr2026.pdf | B4: Apr-2026 | C4: 46138 | D4: Visa ***4821 | E4: Meta Platforms - Ad Spend Top-up | F4: 3142.31 | G4: =IFERROR(IF(ISNUMBER(SEARCH(Assumptions!$C$5,E4)),Assumptions!$D$5,IF(ISNUMBER(SEARCH(Assumptions!$C$6,E4)),Assumptions!$D$6,IF(ISNUMBER(SEARCH(Assumptions!$C$7,E4)),Assumptions!$D$7,"Other Services"))),"Other Services") -> Other Services
A5: CC_Statement_Apr2026.pdf | B5: Apr-2026 | C5: 46129 | D5: Visa ***4821 | E5: AWS Cloud Hosting | F5: 762.28 | G5: =IF(E5="","",IFERROR(IF(ISNUMBER(SEARCH(Assumptions!$C$5,E5)),Assumptions!$D$5,IF(ISNUMBER(SEARCH(Assumptions!$C$6,E5)),Assumptions!$D$6,IF(ISNUMBER(SEARCH(Assumptions!$C$7,E5)),Assumptions!$D$7,"Other Services"))),"Other Services")) -> Other Services
A6: CC_Statement_Apr2026.pdf | B6: Apr-2026 | C6: 46129 | D6: Visa ***4821 | E6: Office Supplies - Depot | F6: 1069.63 | G6: =IF(E6="","",IFERROR(IF(ISNUMBER(SEARCH(Assumptions!$C$5,E6)),Assumptions!$D$5,IF(ISNUMBER(SEARCH(Assumptions!$C$6,E6)),Assumptions!$D$6,IF(ISNUMBER(SEARCH(Assumptions!$C$7,E6)),Assumptions!$D$7,"Other Services"))),"Other Services")) -> Other Services
A7: CC_Statement_Apr2026.pdf | B7: Apr-2026 | C7: 46132 | D7: Visa ***4821 | E7: Google Workspace Subscription | F7: 972.89 | G7: =IF(E7="","",IFERROR(IF(ISNUMBER(SEARCH(Assumptions!$C$5,E7)),Assumptions!$D$5,IF(ISNUMBER(SEARCH(Assumptions!$C$6,E7)),Assumptions!$D$6,IF(ISNUMBER(SEARCH(Assumptions!$C$7,E7)),Assumptions!$D$7,"Other Services"))),"Other Services")) -> Subscription
A8: CC_Statement_Apr2026.pdf | B8: Apr-2026 | C8: 46126 | D8: Visa ***4821 | E8: Careem - Business Travel | F8: 1199.6 | G8: =IF(E8="","",IFERROR(IF(ISNUMBER(SEARCH(Assumptions!$C$5,E8)),Assumptions!$D$5,IF(ISNUMBER(SEARCH(Assumptions!$C$6,E8)),Assumptions!$D$6,IF(ISNUMBER(SEARCH(Assumptions!$C$7,E8)),Assumptions!$D$7,"Other Services"))),"Other Services")) -> Other Services
A9: CC_Statement_Apr2026.pdf | B9: Apr-2026 | C9: 46139 | D9: Visa ***4821 | E9: Careem - Business Travel | F9: 448.14 | G9: =IF(E9="","",IFERROR(IF(ISNUMBER(SEARCH(Assumptions!$C$5,E9)),Assumptions!$D$5,IF(ISNUMBER(SEARCH(Assumptions!$C$6,E9)),Assumptions!$D$6,IF(ISNUMBER(SEARCH(Assumptions!$C$7,E9)),Assumptions!$D$7,"Other Services"))),"Other Services")) -> Other Services
A10: CC_Statement_Apr2026.pdf | B10: Apr-2026 | C10: 46122 | D10: Visa ***4821 | E10: Office Supplies - Depot | F10: 158.18 | G10: =IF(E10="","",IFERROR(IF(ISNUMBER(SEARCH(Assumptions!$C$5,E10)),Assumptions!$D$5,IF(ISNUMBER(SEARCH(Assumptions!$C$6,E10)),Assumptions!$D$6,IF(ISNUMBER(SEARCH(Assumptions!$C$7,E10)),Assumptions!$D$7,"Other Services"))),"Other Services")) -> Other Services
A11: CC_Statement_Apr2026.pdf | B11: Apr-2026 | C11: 46115 | D11: Visa ***4821 | E11: Zoom Subscription | F11: 3227.77 | G11: =IF(E11="","",IFERROR(IF(ISNUMBER(SEARCH(Assumptions!$C$5,E11)),Assumptions!$D$5,IF(ISNUMBER(SEARCH(Assumptions!$C$6,E11)),Assumptions!$D$6,IF(ISNUMBER(SEARCH(Assumptions!$C$7,E11)),Assumptions!$D$7,"Other Services"))),"Other Services")) -> Subscription
A12: CC_Statement_Apr2026.pdf | B12: Apr-2026 | C12: 46130 | D12: Visa ***4821 | E12: AWS Cloud Hosting | F12: 1638.18 | G12: =IF(E12="","",IFERROR(IF(ISNUMBER(SEARCH(Assumptions!$C$5,E12)),Assumptions!$D$5,IF(ISNUMBER(SEARCH(Assumptions!$C$6,E12)),Assumptions!$D$6,IF(ISNUMBER(SEARCH(Assumptions!$C$7,E12)),Assumptions!$D$7,"Other Services"))),"Other Services")) -> Other Services
A13: CC_Statement_Apr2026.pdf | B13: Apr-2026 | C13: 46138 | D13: Visa ***4821 | E13: AWS Cloud Hosting | F13: 416.84 | G13: =IF(E13="","",IFERROR(IF(ISNUMBER(SEARCH(Assumptions!$C$5,E13)),Assumptions!$D$5,IF(ISNUMBER(SEARCH(Assumptions!$C$6,E13)),Assumptions!$D$6,IF(ISNUMBER(SEARCH(Assumptions!$C$7,E13)),Assumptions!$D$7,"Other Services"))),"Other Services")) -> Other Services
A14: CC_Statement_May2026.pdf | B14: May-2026 | C14: 46146 | D14: Visa ***4821 | E14: Meta Platforms - Ad Spend Top-up | F14: 2060.51 | G14: =IF(E14="","",IFERROR(IF(ISNUMBER(SEARCH(Assumptions!$C$5,E14)),Assumptions!$D$5,IF(ISNUMBER(SEARCH(Assumptions!$C$6,E14)),Assumptions!$D$6,IF(ISNUMBER(SEARCH(Assumptions!$C$7,E14)),Assumptions!$D$7,"Other Services"))),"Other Services")) -> Other Services
A15: CC_Statement_May2026.pdf | B15: May-2026 | C15: 46167 | D15: Visa ***4821 | E15: WhatsApp Business API - Twilio | F15: 2996.56 | G15: =IF(E15="","",IFERROR(IF(ISNUMBER(SEARCH(Assumptions!$C$5,E15)),Assumptions!$D$5,IF(ISNUMBER(SEARCH(Assumptions!$C$6,E15)),Assumptions!$D$6,IF(ISNUMBER(SEARCH(Assumptions!$C$7,E15)),Assumptions!$D$7,"Other Services"))),"Other Services")) -> WhatsApp
A16: CC_Statement_May2026.pdf | B16: May-2026 | C16: 46164 | D16: Visa ***4821 | E16: Freelancer.com - Development Contractor | F16: 3463.11 | G16: =IF(E16="","",IFERROR(IF(ISNUMBER(SEARCH(Assumptions!$C$5,E16)),Assumptions!$D$5,IF(ISNUMBER(SEARCH(Assumptions!$C$6,E16)),Assumptions!$D$6,IF(ISNUMBER(SEARCH(Assumptions!$C$7,E16)),Assumptions!$D$7,"Other Services"))),"Other Services")) -> Development
... A33: CC_Statement_Jun2026.pdf | B33: Jun-2026 | C33: 46180 | D33: Visa ***4821 | E33: AWS Cloud Hosting | F33: 1144.57 | G33: =IF(E33="","",IFERROR(IF(ISNUMBER(SEARCH(Assumptions!$C$5,E33)),Assumptions!$D$5,IF(ISNUMBER(SEARCH(Assumptions!$C$6,E33)),Assumptions!$D$6,IF(ISNUMBER(SEARCH(Assumptions!$C$7,E33)),Assumptions!$D$7,"Other Services"))),"Other Services")) -> Other Services
G34: =IF(E34="","",IFERROR(IF(ISNUMBER(SEARCH(Assumptions!$C$5,E34)),Assumptions!$D$5,IF(ISNUMBER(SEARCH(Assumptions!$C$6,E34)),Assumptions!$D$6,IF(ISNUMBER(SEARCH(Assumptions!$C$7,E34)),Assumptions!$D$7,"Other Services"))),"Other Services"))
G35: =IF(E35="","",IFERROR(IF(ISNUMBER(SEARCH(Assumptions!$C$5,E35)),Assumptions!$D$5,IF(ISNUMBER(SEARCH(Assumptions!$C$6,E35)),Assumptions!$D$6,IF(ISNUMBER(SEARCH(Assumptions!$C$7,E35)),Assumptions!$D$7,"Other Services"))),"Other Services"))
G36: =IF(E36="","",IFERROR(IF(ISNUMBER(SEARCH(Assumptions!$C$5,E36)),Assumptions!$D$5,IF(ISNUMBER(SEARCH(Assumptions!$C$6,E36)),Assumptions!$D$6,IF(ISNUMBER(SEARCH(Assumptions!$C$7,E36)),Assumptions!$D$7,"Other Services"))),"Other Services"))
G37: =IF(E37="","",IFERROR(IF(ISNUMBER(SEARCH(Assumptions!$C$5,E37)),Assumptions!$D$5,IF(ISNUMBER(SEARCH(Assumptions!$C$6,E37)),Assumptions!$D$6,IF(ISNUMBER(SEARCH(Assumptions!$C$7,E37)),Assumptions!$D$7,"Other Services"))),"Other Services"))
G38: =IF(E38="","",IFERROR(IF(ISNUMBER(SEARCH(Assumptions!$C$5,E38)),Assumptions!$D$5,IF(ISNUMBER(SEARCH(Assumptions!$C$6,E38)),Assumptions!$D$6,IF(ISNUMBER(SEARCH(Assumptions!$C$7,E38)),Assumptions!$D$7,"Other Services"))),"Other Services"))
G39: =IF(E39="","",IFERROR(IF(ISNUMBER(SEARCH(Assumptions!$C$5,E39)),Assumptions!$D$5,IF(ISNUMBER(SEARCH(Assumptions!$C$6,E39)),Assumptions!$D$6,IF(ISNUMBER(SEARCH(Assumptions!$C$7,E39)),Assumptions!$D$7,"Other Services"))),"Other Services"))
G40: =IF(E40="","",IFERROR(IF(ISNUMBER(SEARCH(Assumptions!$C$5,E40)),Assumptions!$D$5,IF(ISNUMBER(SEARCH(Assumptions!$C$6,E40)),Assumptions!$D$6,IF(ISNUMBER(SEARCH(Assumptions!$C$7,E40)),Assumptions!$D$7,"Other Services"))),"Other Services"))
G41: =IF(E41="","",IFERROR(IF(ISNUMBER(SEARCH(Assumptions!$C$5,E41)),Assumptions!$D$5,IF(ISNUMBER(SEARCH(Assumptions!$C$6,E41)),Assumptions!$D$6,IF(ISNUMBER(SEARCH(Assumptions!$C$7,E41)),Assumptions!$D$7,"Other Services"))),"Other Services"))
G42: =IF(E42="","",IFERROR(IF(ISNUMBER(SEARCH(Assumptions!$C$5,E42)),Assumptions!$D$5,IF(ISNUMBER(SEARCH(Assumptions!$C$6,E42)),Assumptions!$D$6,IF(ISNUMBER(SEARCH(Assumptions!$C$7,E42)),Assumptions!$D$7,"Other Services"))),"Other Services"))
G43: =IF(E43="","",IFERROR(IF(ISNUMBER(SEARCH(Assumptions!$C$5,E43)),Assumptions!$D$5,IF(ISNUMBER(SEARCH(Assumptions!$C$6,E43)),Assumptions!$D$6,IF(ISNUMBER(SEARCH(Assumptions!$C$7,E43)),Assumptions!$D$7,"Other Services"))),"Other Services"))
G44: =IF(E44="","",IFERROR(IF(ISNUMBER(SEARCH(Assumptions!$C$5,E44)),Assumptions!$D$5,IF(ISNUMBER(SEARCH(Assumptions!$C$6,E44)),Assumptions!$D$6,IF(ISNUMBER(SEARCH(Assumptions!$C$7,E44)),Assumptions!$D$7,"Other Services"))),"Other Services"))
G45: =IF(E45="","",IFERROR(IF(ISNUMBER(SEARCH(Assumptions!$C$5,E45)),Assumptions!$D$5,IF(ISNUMBER(SEARCH(Assumptions!$C$6,E45)),Assumptions!$D$6,IF(ISNUMBER(SEARCH(Assumptions!$C$7,E45)),Assumptions!$D$7,"Other Services"))),"Other Services"))
... G5003: =IF(E5003="","",IFERROR(IF(ISNUMBER(SEARCH(Assumptions!$C$5,E5003)),Assumptions!$D$5,IF(ISNUMBER(SEARCH(Assumptions!$C$6,E5003)),Assumptions!$D$6,IF(ISNUMBER(SEARCH(Assumptions!$C$7,E5003)),Assumptions!$D$7,"Other Services"))),"Other Services"))

Sheet Customer_Invoices_Upload
A1: CUSTOMER INVOICES (AR) — UPLOAD ZONE
A2: HOW TO USE: Upload customer invoice files (PDF or Word) in the chat and ask Claude to extract them into this tab — one row per invoice. Or paste manually if you already have the data. Country is auto-looked-up from the Assumptions customer→country map (add new customers there if missing). These rows flow into Revenue_Summary and Receivables alongside any Xero invoices, so they are additive, not a duplicate — do not also enter the same invoice in Xero_Raw. This tab is pre-formulated for up to 5,000 rows (through row 5003) — just paste your data starting row 4.
A3: Source File | B3: Invoice Date | C3: Due Date | D3: Invoice No. | E3: Customer | F3: Country (auto) | G3: Description / Line Item | H3: Amount (AED) | I3: Status | J3: Category (auto)
A4: CustInvoice_5002.pdf | B4: 46127 | C4: 46157 | D4: INV-5002 | E4: Misfit Technologies Pte Ltd | F4: =IFERROR(VLOOKUP(E4,Assumptions!$G$5:$H$16,2,0),"Other") -> Singapore | G4: WhatsApp API - Monthly Usage - Apr-2026 | H4: 2862.59 | I4: Awaiting Payment | J4: =IFERROR(IF(ISNUMBER(SEARCH(Assumptions!$C$5,G4)),Assumptions!$D$5,IF(ISNUMBER(SEARCH(Assumptions!$C$6,G4)),Assumptions!$D$6,IF(ISNUMBER(SEARCH(Assumptions!$C$7,G4)),Assumptions!$D$7,"Other Services"))),"Other Services") -> WhatsApp
A5: CustInvoice_5003.pdf | B5: 46118 | C5: 46148 | D5: INV-5003 | E5: Growth X Ventures LLC | F5: =IF(E5="","",IFERROR(VLOOKUP(E5,Assumptions!$G$5:$H$16,2,0),"Other")) -> UAE | G5: WhatsApp API - Monthly Usage - Apr-2026 | H5: 10453.91 | I5: Paid | J5: =IF(G5="","",IFERROR(IF(ISNUMBER(SEARCH(Assumptions!$C$5,G5)),Assumptions!$D$5,IF(ISNUMBER(SEARCH(Assumptions!$C$6,G5)),Assumptions!$D$6,IF(ISNUMBER(SEARCH(Assumptions!$C$7,G5)),Assumptions!$D$7,"Other Services"))),"Other Services")) -> WhatsApp
A6: CustInvoice_5004.pdf | B6: 46118 | C6: 46148 | D6: INV-5004 | E6: Al Fardan Exchange - Sole Proprietorship L.L.C | F6: =IF(E6="","",IFERROR(VLOOKUP(E6,Assumptions!$G$5:$H$16,2,0),"Other")) -> UAE | G6: WhatsApp API - Monthly Usage - Apr-2026 | H6: 10317.27 | I6: Overdue | J6: =IF(G6="","",IFERROR(IF(ISNUMBER(SEARCH(Assumptions!$C$5,G6)),Assumptions!$D$5,IF(ISNUMBER(SEARCH(Assumptions!$C$6,G6)),Assumptions!$D$6,IF(ISNUMBER(SEARCH(Assumptions!$C$7,G6)),Assumptions!$D$7,"Other Services"))),"Other Services")) -> WhatsApp
A7: CustInvoice_5005.pdf | B7: 46132 | C7: 46162 | D7: INV-5005 | E7: Al Fardan Exchange - Sole Proprietorship L.L.C | F7: =IF(E7="","",IFERROR(VLOOKUP(E7,Assumptions!$G$5:$H$16,2,0),"Other")) -> UAE | G7: WhatsApp API - Monthly Usage - Apr-2026 | H7: 11128.21 | I7: Overdue | J7: =IF(G7="","",IFERROR(IF(ISNUMBER(SEARCH(Assumptions!$C$5,G7)),Assumptions!$D$5,IF(ISNUMBER(SEARCH(Assumptions!$C$6,G7)),Assumptions!$D$6,IF(ISNUMBER(SEARCH(Assumptions!$C$7,G7)),Assumptions!$D$7,"Other Services"))),"Other Services")) -> WhatsApp
A8: CustInvoice_5006.pdf | B8: 46117 | C8: 46147 | D8: INV-5006 | E8: Al Fardan Exchange - Sole Proprietorship L.L.C | F8: =IF(E8="","",IFERROR(VLOOKUP(E8,Assumptions!$G$5:$H$16,2,0),"Other")) -> UAE | G8: Subscription - Pro Plan - Apr-2026 | H8: 1679.78 | I8: Paid | J8: =IF(G8="","",IFERROR(IF(ISNUMBER(SEARCH(Assumptions!$C$5,G8)),Assumptions!$D$5,IF(ISNUMBER(SEARCH(Assumptions!$C$6,G8)),Assumptions!$D$6,IF(ISNUMBER(SEARCH(Assumptions!$C$7,G8)),Assumptions!$D$7,"Other Services"))),"Other Services")) -> Subscription
A9: CustInvoice_5007.pdf | B9: 46144 | C9: 46174 | D9: INV-5007 | E9: Growth X Ventures LLC | F9: =IF(E9="","",IFERROR(VLOOKUP(E9,Assumptions!$G$5:$H$16,2,0),"Other")) -> UAE | G9: Subscription - Pro Plan - May-2026 | H9: 13175.39 | I9: Awaiting Payment | J9: =IF(G9="","",IFERROR(IF(ISNUMBER(SEARCH(Assumptions!$C$5,G9)),Assumptions!$D$5,IF(ISNUMBER(SEARCH(Assumptions!$C$6,G9)),Assumptions!$D$6,IF(ISNUMBER(SEARCH(Assumptions!$C$7,G9)),Assumptions!$D$7,"Other Services"))),"Other Services")) -> Subscription
A10: CustInvoice_5008.pdf | B10: 46151 | C10: 46181 | D10: INV-5008 | E10: I Farmer Pte Ltd | F10: =IF(E10="","",IFERROR(VLOOKUP(E10,Assumptions!$G$5:$H$16,2,0),"Other")) -> Singapore | G10: WhatsApp API - Monthly Usage - May-2026 | H10: 11937.43 | I10: Paid | J10: =IF(G10="","",IFERROR(IF(ISNUMBER(SEARCH(Assumptions!$C$5,G10)),Assumptions!$D$5,IF(ISNUMBER(SEARCH(Assumptions!$C$6,G10)),Assumptions!$D$6,IF(ISNUMBER(SEARCH(Assumptions!$C$7,G10)),Assumptions!$D$7,"Other Services"))),"Other Services")) -> WhatsApp
A11: CustInvoice_5009.pdf | B11: 46149 | C11: 46179 | D11: INV-5009 | E11: I Farmer Pte Ltd | F11: =IF(E11="","",IFERROR(VLOOKUP(E11,Assumptions!$G$5:$H$16,2,0),"Other")) -> Singapore | G11: Custom Development - Sprint Invoice - May-2026 | H11: 2815.34 | I11: Paid | J11: =IF(G11="","",IFERROR(IF(ISNUMBER(SEARCH(Assumptions!$C$5,G11)),Assumptions!$D$5,IF(ISNUMBER(SEARCH(Assumptions!$C$6,G11)),Assumptions!$D$6,IF(ISNUMBER(SEARCH(Assumptions!$C$7,G11)),Assumptions!$D$7,"Other Services"))),"Other Services")) -> Development
A12: CustInvoice_5010.pdf | B12: 46147 | C12: 46177 | D12: INV-5010 | E12: Misfit Technologies Pte Ltd | F12: =IF(E12="","",IFERROR(VLOOKUP(E12,Assumptions!$G$5:$H$16,2,0),"Other")) -> Singapore | G12: Custom Development - Sprint Invoice - May-2026 | H12: 21750.95 | I12: Overdue | J12: =IF(G12="","",IFERROR(IF(ISNUMBER(SEARCH(Assumptions!$C$5,G12)),Assumptions!$D$5,IF(ISNUMBER(SEARCH(Assumptions!$C$6,G12)),Assumptions!$D$6,IF(ISNUMBER(SEARCH(Assumptions!$C$7,G12)),Assumptions!$D$7,"Other Services"))),"Other Services")) -> Development
A13: CustInvoice_5011.pdf | B13: 46152 | C13: 46182 | D13: INV-5011 | E13: I Farmer Pte Ltd | F13: =IF(E13="","",IFERROR(VLOOKUP(E13,Assumptions!$G$5:$H$16,2,0),"Other")) -> Singapore | G13: Custom Development - Sprint Invoice - May-2026 | H13: 14640.03 | I13: Awaiting Payment | J13: =IF(G13="","",IFERROR(IF(ISNUMBER(SEARCH(Assumptions!$C$5,G13)),Assumptions!$D$5,IF(ISNUMBER(SEARCH(Assumptions!$C$6,G13)),Assumptions!$D$6,IF(ISNUMBER(SEARCH(Assumptions!$C$7,G13)),Assumptions!$D$7,"Other Services"))),"Other Services")) -> Development
A14: CustInvoice_5012.pdf | B14: 46190 | C14: 46220 | D14: INV-5012 | E14: I Farmer Pte Ltd | F14: =IF(E14="","",IFERROR(VLOOKUP(E14,Assumptions!$G$5:$H$16,2,0),"Other")) -> Singapore | G14: Custom Development - Sprint Invoice - Jun-2026 | H14: 13168.55 | I14: Overdue | J14: =IF(G14="","",IFERROR(IF(ISNUMBER(SEARCH(Assumptions!$C$5,G14)),Assumptions!$D$5,IF(ISNUMBER(SEARCH(Assumptions!$C$6,G14)),Assumptions!$D$6,IF(ISNUMBER(SEARCH(Assumptions!$C$7,G14)),Assumptions!$D$7,"Other Services"))),"Other Services")) -> Development
A15: CustInvoice_5013.pdf | B15: 46178 | C15: 46208 | D15: INV-5013 | E15: Al Fardan Exchange - Sole Proprietorship L.L.C | F15: =IF(E15="","",IFERROR(VLOOKUP(E15,Assumptions!$G$5:$H$16,2,0),"Other")) -> UAE | G15: WhatsApp API - Monthly Usage - Jun-2026 | H15: 2303.99 | I15: Overdue | J15: =IF(G15="","",IFERROR(IF(ISNUMBER(SEARCH(Assumptions!$C$5,G15)),Assumptions!$D$5,IF(ISNUMBER(SEARCH(Assumptions!$C$6,G15)),Assumptions!$D$6,IF(ISNUMBER(SEARCH(Assumptions!$C$7,G15)),Assumptions!$D$7,"Other Services"))),"Other Services")) -> WhatsApp
A16: CustInvoice_5014.pdf | B16: 46192 | C16: 46222 | D16: INV-5014 | E16: Al Fardan Exchange - Sole Proprietorship L.L.C | F16: =IF(E16="","",IFERROR(VLOOKUP(E16,Assumptions!$G$5:$H$16,2,0),"Other")) -> UAE | G16: Custom Development - Sprint Invoice - Jun-2026 | H16: 19304.61 | I16: Paid | J16: =IF(G16="","",IFERROR(IF(ISNUMBER(SEARCH(Assumptions!$C$5,G16)),Assumptions!$D$5,IF(ISNUMBER(SEARCH(Assumptions!$C$6,G16)),Assumptions!$D$6,IF(ISNUMBER(SEARCH(Assumptions!$C$7,G16)),Assumptions!$D$7,"Other Services"))),"Other Services")) -> Development
... A18: CustInvoice_5016.pdf | B18: 46184 | C18: 46214 | D18: INV-5016 | E18: United Homeware Company (Nice) | F18: =IF(E18="","",IFERROR(VLOOKUP(E18,Assumptions!$G$5:$H$16,2,0),"Other")) -> UAE | G18: Subscription - Pro Plan - Jun-2026 | H18: 21404.62 | I18: Paid | J18: =IF(G18="","",IFERROR(IF(ISNUMBER(SEARCH(Assumptions!$C$5,G18)),Assumptions!$D$5,IF(ISNUMBER(SEARCH(Assumptions!$C$6,G18)),Assumptions!$D$6,IF(ISNUMBER(SEARCH(Assumptions!$C$7,G18)),Assumptions!$D$7,"Other Services"))),"Other Services")) -> Subscription
F19: =IF(E19="","",IFERROR(VLOOKUP(E19,Assumptions!$G$5:$H$16,2,0),"Other")) | J19: =IF(G19="","",IFERROR(IF(ISNUMBER(SEARCH(Assumptions!$C$5,G19)),Assumptions!$D$5,IF(ISNUMBER(SEARCH(Assumptions!$C$6,G19)),Assumptions!$D$6,IF(ISNUMBER(SEARCH(Assumptions!$C$7,G19)),Assumptions!$D$7,"Other Services"))),"Other Services"))
F20: =IF(E20="","",IFERROR(VLOOKUP(E20,Assumptions!$G$5:$H$16,2,0),"Other")) | J20: =IF(G20="","",IFERROR(IF(ISNUMBER(SEARCH(Assumptions!$C$5,G20)),Assumptions!$D$5,IF(ISNUMBER(SEARCH(Assumptions!$C$6,G20)),Assumptions!$D$6,IF(ISNUMBER(SEARCH(Assumptions!$C$7,G20)),Assumptions!$D$7,"Other Services"))),"Other Services"))
F21: =IF(E21="","",IFERROR(VLOOKUP(E21,Assumptions!$G$5:$H$16,2,0),"Other")) | J21: =IF(G21="","",IFERROR(IF(ISNUMBER(SEARCH(Assumptions!$C$5,G21)),Assumptions!$D$5,IF(ISNUMBER(SEARCH(Assumptions!$C$6,G21)),Assumptions!$D$6,IF(ISNUMBER(SEARCH(Assumptions!$C$7,G21)),Assumptions!$D$7,"Other Services"))),"Other Services"))
F22: =IF(E22="","",IFERROR(VLOOKUP(E22,Assumptions!$G$5:$H$16,2,0),"Other")) | J22: =IF(G22="","",IFERROR(IF(ISNUMBER(SEARCH(Assumptions!$C$5,G22)),Assumptions!$D$5,IF(ISNUMBER(SEARCH(Assumptions!$C$6,G22)),Assumptions!$D$6,IF(ISNUMBER(SEARCH(Assumptions!$C$7,G22)),Assumptions!$D$7,"Other Services"))),"Other Services"))
F23: =IF(E23="","",IFERROR(VLOOKUP(E23,Assumptions!$G$5:$H$16,2,0),"Other")) | J23: =IF(G23="","",IFERROR(IF(ISNUMBER(SEARCH(Assumptions!$C$5,G23)),Assumptions!$D$5,IF(ISNUMBER(SEARCH(Assumptions!$C$6,G23)),Assumptions!$D$6,IF(ISNUMBER(SEARCH(Assumptions!$C$7,G23)),Assumptions!$D$7,"Other Services"))),"Other Services"))
F24: =IF(E24="","",IFERROR(VLOOKUP(E24,Assumptions!$G$5:$H$16,2,0),"Other")) | J24: =IF(G24="","",IFERROR(IF(ISNUMBER(SEARCH(Assumptions!$C$5,G24)),Assumptions!$D$5,IF(ISNUMBER(SEARCH(Assumptions!$C$6,G24)),Assumptions!$D$6,IF(ISNUMBER(SEARCH(Assumptions!$C$7,G24)),Assumptions!$D$7,"Other Services"))),"Other Services"))
F25: =IF(E25="","",IFERROR(VLOOKUP(E25,Assumptions!$G$5:$H$16,2,0),"Other")) | J25: =IF(G25="","",IFERROR(IF(ISNUMBER(SEARCH(Assumptions!$C$5,G25)),Assumptions!$D$5,IF(ISNUMBER(SEARCH(Assumptions!$C$6,G25)),Assumptions!$D$6,IF(ISNUMBER(SEARCH(Assumptions!$C$7,G25)),Assumptions!$D$7,"Other Services"))),"Other Services"))
